<?xml version="1.0"?>
<robot name="holonomic_robot">

  <!-- Colors -->
  <material name="blue">
    <color rgba="0.2 0.2 0.8 1.0"/>
  </material>
  
  <material name="black">
    <color rgba="0.1 0.1 0.1 1.0"/>
  </material>
  
  <material name="red">
    <color rgba="0.8 0.2 0.2 1.0"/>
  </material>

  <!-- Base footprint (ground projection) -->
  <link name="base_footprint"/>

  <joint name="base_joint" type="fixed">
    <parent link="base_footprint"/>
    <child link="base_link"/>
    <origin xyz="0 0 0.05" rpy="0 0 0"/>
  </joint>

  <!-- Base link (chassis) -->
  <link name="base_link">
    <visual>
      <origin xyz="0 0 0.25" rpy="0 0 0"/>
      <geometry>
        <cylinder radius="0.15" length="0.5"/>
      </geometry>
      <material name="blue"/>
    </visual>
    <collision>
      <origin xyz="0 0 0.25" rpy="0 0 0"/>
      <geometry>
        <cylinder radius="0.15" length="0.5"/>
      </geometry>
    </collision>
    <inertial>
      <origin xyz="0 0 0" rpy="0 0 0"/>
      <mass value="5.0"/>
      <inertia ixx="0.0254167" ixy="0.0" ixz="0.0" 
               iyy="0.0254167" iyz="0.0" izz="0.05"/>
    </inertial>
  </link>

  <!-- Front wheel -->
  <link name="front_wheel_link">
    <visual>
      <origin xyz="0 0 0" rpy="1.5708 0 0"/>
      <geometry>
        <cylinder radius="0.05" length="0.04"/>
      </geometry>
      <material name="black"/>
    </visual>
    <collision>
      <origin xyz="0 0 0" rpy="1.5708 0 0"/>
      <geometry>
        <cylinder radius="0.05" length="0.04"/>
      </geometry>
    </collision>
    <inertial>
      <origin xyz="0 0 0" rpy="1.5708 0 0"/>
      <mass value="0.5"/>
      <inertia ixx="0.000729167" ixy="0.0" ixz="0.0" 
               iyy="0.000729167" iyz="0.0" izz="0.00125"/>
    </inertial>
  </link>

  <joint name="front_wheel_joint" type="continuous">
    <parent link="base_link"/>
    <child link="front_wheel_link"/>
    <origin xyz="0.0 0.12 -0.05" rpy="0 0 0"/>
    <axis xyz="0 1 0"/>
  </joint>

  <!-- Left rear wheel -->
  <link name="left_rear_wheel_link">
    <visual>
      <origin xyz="0 0 0" rpy="1.5708 0 0"/>
      <geometry>
        <cylinder radius="0.05" length="0.04"/>
      </geometry>
      <material name="black"/>
    </visual>
    <collision>
      <origin xyz="0 0 0" rpy="1.5708 0 0"/>
      <geometry>
        <cylinder radius="0.05" length="0.04"/>
      </geometry>
    </collision>
    <inertial>
      <origin xyz="0 0 0" rpy="1.5708 0 0"/>
      <mass value="0.5"/>
      <inertia ixx="0.000729167" ixy="0.0" ixz="0.0" 
               iyy="0.000729167" iyz="0.0" izz="0.00125"/>
    </inertial>
  </link>

  <joint name="left_rear_wheel_joint" type="continuous">
    <parent link="base_link"/>
    <child link="left_rear_wheel_link"/>
    <origin xyz="-0.12 -0.0566 -0.05" rpy="0 0 -0.95"/>
    <axis xyz="0 1 0"/>
  </joint>

  <!-- Right rear wheel -->
  <link name="right_rear_wheel_link">
    <visual>
      <origin xyz="0 0 0" rpy="1.5708 0 0"/>
      <geometry>
        <cylinder radius="0.05" length="0.04"/>
      </geometry>
      <material name="black"/>
    </visual>
    <collision>
      <origin xyz="0 0 0" rpy="1.5708 0 0"/>
      <geometry>
        <cylinder radius="0.05" length="0.04"/>
      </geometry>
    </collision>
    <inertial>
      <origin xyz="0 0 0" rpy="1.5708 0 0"/>
      <mass value="0.5"/>
      <inertia ixx="0.000729167" ixy="0.0" ixz="0.0" 
               iyy="0.000729167" iyz="0.0" izz="0.00125"/>
    </inertial>
  </link>

  <joint name="right_rear_wheel_joint" type="continuous">
    <parent link="base_link"/>
    <child link="right_rear_wheel_link"/>
    <origin xyz="0.12 -0.0566 -0.05" rpy="0 0 0.95"/>
    <axis xyz="0 1 0"/>
  </joint>

  <!-- Lidar sensor -->
  <link name="base_scan">
    <visual>
      <origin xyz="0 0 0" rpy="0 0 0"/>
      <geometry>
        <cylinder radius="0.025" length="0.05"/>
      </geometry>
      <material name="red"/>
    </visual>
    <collision>
      <origin xyz="0 0 0" rpy="0 0 0"/>
      <geometry>
        <cylinder radius="0.025" length="0.05"/>
      </geometry>
    </collision>
    <inertial>
      <origin xyz="0 0 0" rpy="0 0 0"/>
      <mass value="0.1"/>
      <inertia ixx="0.0000229167" ixy="0.0" ixz="0.0" 
               iyy="0.0000229167" iyz="0.0" izz="0.00003125"/>
    </inertial>
  </link>

  <joint name="lidar_joint" type="fixed">
    <parent link="base_link"/>
    <child link="base_scan"/>
    <origin xyz="0 0 0.075" rpy="0 0 0"/>
  </joint>

</robot>
